401 response executing GraphQL.
{"errors":[{"message":"permission denied","path":["upsertBucket"],"extensions":{"code":"PERMISSION_ERROR"}}],"data":{"upsertBucket":null}}
[34m[1mwandb[0m: [32m[41mERROR[0m Error while calling W&B API: permission denied (<Response [401]>)
[34m[1mwandb[0m: [32m[41mERROR[0m Invalid or missing api_key.  Run wandb login
Traceback (most recent call last):
  File "/Library/Frameworks/Python.framework/Versions/3.8/lib/python3.8/site-packages/wandb/retry.py", line 95, in __call__
    result = self._call_fn(*args, **kwargs)
  File "/Library/Frameworks/Python.framework/Versions/3.8/lib/python3.8/site-packages/wandb/apis/internal.py", line 114, in execute
    six.reraise(*sys.exc_info())
  File "/Library/Frameworks/Python.framework/Versions/3.8/lib/python3.8/site-packages/six.py", line 703, in reraise
    raise value
  File "/Library/Frameworks/Python.framework/Versions/3.8/lib/python3.8/site-packages/wandb/apis/internal.py", line 108, in execute
    return self.client.execute(*args, **kwargs)
  File "/Library/Frameworks/Python.framework/Versions/3.8/lib/python3.8/site-packages/gql/client.py", line 52, in execute
    result = self._get_result(document, *args, **kwargs)
  File "/Library/Frameworks/Python.framework/Versions/3.8/lib/python3.8/site-packages/gql/client.py", line 60, in _get_result
    return self.transport.execute(document, *args, **kwargs)
  File "/Library/Frameworks/Python.framework/Versions/3.8/lib/python3.8/site-packages/gql/transport/requests.py", line 39, in execute
    request.raise_for_status()
  File "/Library/Frameworks/Python.framework/Versions/3.8/lib/python3.8/site-packages/requests/models.py", line 941, in raise_for_status
    raise HTTPError(http_error_msg, response=self)
requests.exceptions.HTTPError: 401 Client Error: Unauthorized for url: https://api.wandb.ai/graphql

During handling of the above exception, another exception occurred:

Traceback (most recent call last):
  File "/Library/Frameworks/Python.framework/Versions/3.8/lib/python3.8/site-packages/wandb/apis/__init__.py", line 72, in wrapper
    return func(*args, **kwargs)
  File "/Library/Frameworks/Python.framework/Versions/3.8/lib/python3.8/site-packages/wandb/apis/internal.py", line 784, in upsert_run
    response = self.gql(
  File "/Library/Frameworks/Python.framework/Versions/3.8/lib/python3.8/site-packages/wandb/retry.py", line 102, in __call__
    if not check_retry_fn(e):
  File "/Library/Frameworks/Python.framework/Versions/3.8/lib/python3.8/site-packages/wandb/util.py", line 570, in no_retry_auth
    raise CommError("Invalid or missing api_key.  Run wandb login" + extra)
wandb.apis.CommError: Invalid or missing api_key.  Run wandb login

During handling of the above exception, another exception occurred:

Traceback (most recent call last):
  File "/Users/andreatamburri/Documents/GitHub/CoughCNN/spectro/model.py", line 189, in <module>
    model = Model("Spectro3", config, hyper=True, hyper_project="CoughDetectionv3", extra=(x_extra, y_extra))
  File "/Users/andreatamburri/Documents/GitHub/CoughCNN/spectro/model.py", line 60, in __init__
    wandb.run.save()
  File "/Library/Frameworks/Python.framework/Versions/3.8/lib/python3.8/site-packages/wandb/wandb_run.py", line 416, in save
    upsert_result = api.upsert_run(id=id or self.storage_id, name=self.id, commit=api.git.last_commit,
  File "/Library/Frameworks/Python.framework/Versions/3.8/lib/python3.8/site-packages/wandb/apis/__init__.py", line 108, in wrapper
    six.reraise(CommError, CommError(
  File "/Library/Frameworks/Python.framework/Versions/3.8/lib/python3.8/site-packages/six.py", line 702, in reraise
    raise value.with_traceback(tb)
  File "/Library/Frameworks/Python.framework/Versions/3.8/lib/python3.8/site-packages/wandb/apis/__init__.py", line 72, in wrapper
    return func(*args, **kwargs)
  File "/Library/Frameworks/Python.framework/Versions/3.8/lib/python3.8/site-packages/wandb/apis/internal.py", line 784, in upsert_run
    response = self.gql(
  File "/Library/Frameworks/Python.framework/Versions/3.8/lib/python3.8/site-packages/wandb/retry.py", line 102, in __call__
    if not check_retry_fn(e):
  File "/Library/Frameworks/Python.framework/Versions/3.8/lib/python3.8/site-packages/wandb/util.py", line 570, in no_retry_auth
    raise CommError("Invalid or missing api_key.  Run wandb login" + extra)
wandb.apis.CommError: Invalid or missing api_key.  Run wandb login
